Workbook

Sheet Lease Schedule blank
A2: 1 | B2: Lease Obligation Analysis: *Name here*
A4: 2 | B4: *Property name here* | E4: Current Remaining Obligations:
E5: Total Remaining Obligation: | F5: =IFERROR(_xlfn.XLOOKUP($C$13,$C$75:$C$198,$P$75:$P$198,"",0),INDEX($P$75:$P$198,MATCH($C$13,$C$75:$C$198,0))) -> 0
B6: Lease Drivers | E6: Remaining Base Rent: | F6: =IFERROR(_xlfn.XLOOKUP($C$13,$C$75:$C$198,$Q$75:$Q$198,"",0),INDEX($Q$75:$Q$198,MATCH($C$13,$C$75:$C$198,0))) -> 0
A7: 3 | B7: Rentable SF | E7: Remaining Nets: | F7: =IFERROR(_xlfn.XLOOKUP($C$13,$C$75:$C$198,$R$75:$R$198,"",0),INDEX($R$75:$R$198,MATCH($C$13,$C$75:$C$198,0))) -> 0
A8: 4 | B8: Lease Commencement Date | E8: Remaining Other Charges: | F8: =IFERROR(_xlfn.XLOOKUP($C$13,$C$75:$C$198,$S$75:$S$198,"",0),INDEX($S$75:$S$198,MATCH($C$13,$C$75:$C$198,0))) -> 0
A9: 5 | B9: Rent Commencement Date
A10: 6 | B10: Total Lease Term (Months): | C10: =DATEDIF(C8,C11,"M")+1 -> 1
A11: 7 | B11: Lease Expiration Date | E11: Exit & Renegotiation comparisons
A12: 8 | B12: Effective Date of Analysis: | E12: Discount Rate: | F12: 0.07
A13: 9 | B13: Effective Month #: | C13: =IFERROR(MATCH(C12,A75:A198,1),1) -> 1 | E13: SCENARIO COMPARISON - Renegotiation | F13: Effective Date of Analysis: | G13: =C12 -> 0
B14: Months Remaining: | C14: =MAX(0,C10-C13+1) -> 1 | F14: Base Case | G14: Modest | H14: Material | I14: Significant
B15: Month # of effective date: | C15: =C13 -> 1 | E15: % Discount | F15: 0 | G15: 0.1 | H15: 0.2 | I15: 0.3
B16: Months until next base rent escalation: | C16: =12-MOD(C13-1,12) -> 12 | E16: Monthly Base Rent | F16: =INDEX(E$75:E$198,MATCH($C$13,C$75:C$198,0)) -> 0 | G16: =$F$16*(1-G15) -> 0 | H16: =$F$16*(1-H15) -> 0 | I16: =$F$16*(1-I15) -> 0
E17: Base/$PSF | F17: =IF($C$7=0,0,F16/$C$7) -> 0 | G17: =IF($C$7=0,0,G16/$C$7) -> 0 | H17: =IF($C$7=0,0,H16/$C$7) -> 0 | I17: =IF($C$7=0,0,I16/$C$7) -> 0
B18: Monthly Rent Breakdown: | E18: Additional Rent (CAMs + Nets) | F18: =INDEX(M$75:M$198,MATCH($C$13,C$75:C$198,0)) -> 0 | G18: =F18 -> 0 | H18: =G18 -> 0 | I18: =H18 -> 0
B19: Date: | C19: =C12 -> 0 | E19: Total Occupancy Cost | F19: =F16+F18 -> 0 | G19: =G16+G18 -> 0 | H19: =H16+H18 -> 0 | I19: =I16+I18 -> 0
B20: Month: | C20: =TEXT(C12,"MMMM") -> January | E20: Effective $/PSF | F20: =IF($C$7=0,0,F19/$C$7) -> 0 | G20: =IF($C$7=0,0,G19/$C$7) -> 0 | H20: =IF($C$7=0,0,H19/$C$7) -> 0 | I20: =IF($C$7=0,0,I19/$C$7) -> 0
A21: 10 | B21: Scheduled Base Rent | E21: Lease Obligation (FV) | F21: {=SUMPRODUCT(($C$75:$C$198>=IF($C$13=0,1,$C$13))*N$75:N$198)} -> 0 | G21: {=SUMPRODUCT(($C$75:$C$198>=IF($C$13=0,1,$C$13))*T$75:T$198)} -> 0 | H21: {=SUMPRODUCT(($C$75:$C$198>=IF($C$13=0,1,$C$13))*U$75:U$198)} -> 0 | I21: {=SUMPRODUCT(($C$75:$C$198>=IF($C$13=0,1,$C$13))*V$75:V$198)} -> 0
A22: 11 | B22: Insurance Year 1 Monthly Rate ($) | E22: Gross Savings vs Base ($) | F22: =0 -> 0 | G22: =F21-G21 -> 0 | H22: =F21-H21 -> 0 | I22: =F21-I21 -> 0
A23: 12 | B23: Taxes Year 1 Monthly Rate ($) | E23: (+)Free Rent | G23: =G16*$F$23 -> 0 | H23: =H16*$F$23 -> 0 | I23: =I16*$F$23 -> 0
B24: CAMS Year 1 Monthly Rate ($) | E24: (+)TI | G24: =$F$24*$C$7 -> 0 | H24: =$F$24*$C$7 -> 0 | I24: =$F$24*$C$7 -> 0
B25: Security Year 1 Monthly Rate ($) | E25: Total Savings From Base | F25: - | G25: =SUM(G22:G24) -> 0 | H25: =SUM(H22:H24) -> 0 | I25: =SUM(I22:I24) -> 0
B26: Other Items Year 1 Monthly Rate ($) | E26: NPV | F26: {=SUMPRODUCT(($C$75:$C$198>=IF($C$13=0,1,$C$13))*N$75:N$198/(1+$F$12/12)^($C$75:$C$198-IF($C$13=0,0,$C$13)+1))} -> 0 | G26: {=SUMPRODUCT(($C$75:$C$198>=IF($C$13=0,1,$C$13))*T$75:T$198/(1+$F$12/12)^($C$75:$C$198-IF($C$13=0,0,$C$13)+1))} -> 0 | H26: {=SUMPRODUCT(($C$75:$C$198>=IF($C$13=0,1,$C$13))*U$75:U$198/(1+$F$12/12)^($C$75:$C$198-IF($C$13=0,0,$C$13)+1))} -> 0 | I26: {=SUMPRODUCT(($C$75:$C$198>=IF($C$13=0,1,$C$13))*V$75:V$198/(1+$F$12/12)^($C$75:$C$198-IF($C$13=0,0,$C$13)+1))} -> 0
E27: NPV Savings vs Base | F27: - | G27: =F26-G26 -> 0 | H27: =F26-H26 -> 0 | I27: =F26-I26 -> 0
B28: Escalations: | E28: % Savings vs Base | F28: - | G28: =IFERROR((F26-G26)/F26,0) -> 0 | H28: =IFERROR((F26-H26)/F26,0) -> 0 | I28: =IFERROR((F26-I26)/F26,0) -> 0
B29: Annual Base Rent Escalation Rate (%) | E29: Full-Lease FV (all months, no date filter) | F29: =SUM(N75:N198) -> 0 | G29: =SUM(T75:T198) -> 0 | H29: =SUM(U75:U198) -> 0 | I29: =SUM(V75:V198) -> 0
B30: CAMS Annual Escalation Rate (%) | E30: Cross-check: NNN after discount (orphan) | F30: =F18*(1-F15) -> 0 | G30: =F18*(1-G15) -> 0 | H30: =F18*(1-H15) -> 0 | I30: =F18*(1-I15) -> 0
B31: Insurance Annual Escalation Rate (%)
B32: Taxes Annual Escalation Rate (%) | E32: SCENARIO COMPARISON - exit | F32: Effective Date of Analysis: | G32: =C12 -> 0
B33: Security Annual Escalation Rate (%) | F33: Full Obligation | G33: Mild Discount | H33: Moderate Discount | I33: Material Discount | J33: Significant Discount
B34: Other Items Annual Escalation Rate (%) | E34: % Buyout | F34: 0 | G34: 0.2 | H34: 0.3 | I34: 0.4 | J34: 0.5
E35: Monthly Base Rent | F35: =F16 -> 0 | G35: =F35 -> 0 | H35: =F35 -> 0 | I35: =F35 -> 0 | J35: =F35 -> 0
B36: Abatement: | E36: Base/$PSF | F36: =IF($C$7=0,0,F35/$C$7) -> 0 | G36: =IF($C$7=0,0,G35/$C$7) -> 0 | H36: =IF($C$7=0,0,H35/$C$7) -> 0 | I36: =IF($C$7=0,0,I35/$C$7) -> 0 | J36: =IF($C$7=0,0,J35/$C$7) -> 0
B37: Abatement duration (months) | E37: Additional Rent (NNN) | F37: =F18 -> 0 | G37: =F37 -> 0 | H37: =F37 -> 0 | I37: =F37 -> 0
B38: Abatement start | E38: Total Occupancy Cost | F38: =F35+F37 -> 0 | G38: =G35+G37 -> 0 | H38: =H35+H37 -> 0 | I38: =I35+I37 -> 0
B39: Abatement end | E39: Effective $/PSF | F39: =IF($C$7=0,0,F38/$C$7) -> 0 | G39: =IF($C$7=0,0,G38/$C$7) -> 0 | H39: =IF($C$7=0,0,H38/$C$7) -> 0 | I39: =IF($C$7=0,0,I38/$C$7) -> 0
B40: Abatement % of full rent (dependent, don't change) | C40: =IF(C21=0,0,C41/C21) -> 0 | E40: Remaining Obligation (FV) | F40: =F21 -> 0 | G40: =F40*(1-G34) -> 0 | H40: =F40*(1-H34) -> 0 | I40: =F40*(1-I34) -> 0 | J40: =F40*(1-J34) -> 0
A41: 13 | B41: Abatement amt (dollars) | E41: Gross Savings vs Base ($) | F41: =0 -> 0 | G41: =F40-G40 -> 0 | H41: =F40-H40 -> 0 | I41: =F40-I40 -> 0 | J41: =F40-J40 -> 0
A42: 14 | B42: *Additional abatement later in lease? (If yes, view the lease schedule abatement column and hardcode your values) | C42: No | E42: (+)Free Rent | G42: =F35*$F$42 -> 0 | H42: =F35*$F$42 -> 0 | I42: =F35*$F$42 -> 0
...

Sheet Lease Schedule (populated)
A2: 1 | B2: Lease Obligation Analysis: *Name here*
A4: 2 | B4: *Property name here* | E4: Current Remaining Obligations:
E5: Total Remaining Obligation: | F5: =IFERROR(_xlfn.XLOOKUP($C$13,$C$75:$C$198,$P$75:$P$198,"",0),INDEX($P$75:$P$198,MATCH($C$13,$C$75:$C$198,0))) -> 2153223.6
B6: Lease Drivers | E6: Remaining Base Rent: | F6: =IFERROR(_xlfn.XLOOKUP($C$13,$C$75:$C$198,$Q$75:$Q$198,"",0),INDEX($Q$75:$Q$198,MATCH($C$13,$C$75:$C$198,0))) -> 1090337.9
A7: 3 | B7: Rentable SF | C7: 15000 | E7: Remaining Nets: | F7: =IFERROR(_xlfn.XLOOKUP($C$13,$C$75:$C$198,$R$75:$R$198,"",0),INDEX($R$75:$R$198,MATCH($C$13,$C$75:$C$198,0))) -> 1062885.8
A8: 4 | B8: Lease Commencement Date | C8: 43352 | E8: Remaining Other Charges: | F8: =IFERROR(_xlfn.XLOOKUP($C$13,$C$75:$C$198,$S$75:$S$198,"",0),INDEX($S$75:$S$198,MATCH($C$13,$C$75:$C$198,0))) -> 0
A9: 5 | B9: Rent Commencement Date | C9: 43352
A10: 6 | B10: Total Lease Term (Months): | C10: =DATEDIF(C8,C11,"M")+1 -> 121
A11: 7 | B11: Lease Expiration Date | C11: 47005 | E11: Exit & Renegotiation comparisons
A12: 8 | B12: Effective Date of Analysis: | C12: 44205 | E12: Discount Rate: | F12: 0.07
A13: 9 | B13: Effective Month #: | C13: =IFERROR(MATCH(C12,A75:A198,1),1) -> 29 | E13: SCENARIO COMPARISON - Renegotiation | F13: Effective Date of Analysis: | G13: =C12 -> 44205
B14: Months Remaining: | C14: =MAX(0,C10-C13+1) -> 93 | F14: Base Case | G14: Modest | H14: Material | I14: Significant
B15: Month # of effective date: | C15: =C13 -> 29 | E15: % Discount | F15: 0 | G15: 0.1 | H15: 0.2 | I15: 0.3
B16: Months until next base rent escalation: | C16: =12-MOD(C13-1,12) -> 8 | E16: Monthly Base Rent | F16: =INDEX(E$75:E$198,MATCH($C$13,C$75:C$198,0)) -> 10609 | G16: =$F$16*(1-G15) -> 9548.1 | H16: =$F$16*(1-H15) -> 8487.2 | I16: =$F$16*(1-I15) -> 7426.3
E17: Base/$PSF | F17: =IF($C$7=0,0,F16/$C$7) -> 0.70726667 | G17: =IF($C$7=0,0,G16/$C$7) -> 0.63654 | H17: =IF($C$7=0,0,H16/$C$7) -> 0.56581333 | I17: =IF($C$7=0,0,I16/$C$7) -> 0.49508667
B18: Monthly Rent Breakdown: | E18: Additional Rent (CAMs + Nets) | F18: =INDEX(M$75:M$198,MATCH($C$13,C$75:C$198,0)) -> 10258.25 | G18: =F18 -> 10258.25 | H18: =G18 -> 10258.25 | I18: =H18 -> 10258.25
B19: Date: | C19: =C12 -> 44205 | E19: Total Occupancy Cost | F19: =F16+F18 -> 20867.25 | G19: =G16+G18 -> 19806.35 | H19: =H16+H18 -> 18745.45 | I19: =I16+I18 -> 17684.55
B20: Month: | C20: =TEXT(C12,"MMMM") -> January | E20: Effective $/PSF | F20: =IF($C$7=0,0,F19/$C$7) -> 1.39115 | G20: =IF($C$7=0,0,G19/$C$7) -> 1.3204233 | H20: =IF($C$7=0,0,H19/$C$7) -> 1.2496967 | I20: =IF($C$7=0,0,I19/$C$7) -> 1.17897
A21: 10 | B21: Scheduled Base Rent | C21: 10000 | E21: Lease Obligation (FV) | F21: {=SUMPRODUCT(($C$75:$C$198>=IF($C$13=0,1,$C$13))*N$75:N$198)} -> 2153223.6 | G21: {=SUMPRODUCT(($C$75:$C$198>=IF($C$13=0,1,$C$13))*T$75:T$198)} -> 2044189.9 | H21: {=SUMPRODUCT(($C$75:$C$198>=IF($C$13=0,1,$C$13))*U$75:U$198)} -> 1935156.1 | I21: {=SUMPRODUCT(($C$75:$C$198>=IF($C$13=0,1,$C$13))*V$75:V$198)} -> 1826122.3
A22: 11 | B22: Insurance Year 1 Monthly Rate ($) | C22: 1875 | E22: Gross Savings vs Base ($) | F22: =0 -> 0 | G22: =F21-G21 -> 109033.79 | H22: =F21-H21 -> 218067.58 | I22: =F21-I21 -> 327101.36
A23: 12 | B23: Taxes Year 1 Monthly Rate ($) | C23: 3125 | E23: (+)Free Rent | G23: =G16*$F$23 -> 0 | H23: =H16*$F$23 -> 0 | I23: =I16*$F$23 -> 0
B24: CAMS Year 1 Monthly Rate ($) | C24: 3750 | E24: (+)TI | G24: =$F$24*$C$7 -> 0 | H24: =$F$24*$C$7 -> 0 | I24: =$F$24*$C$7 -> 0
B25: Security Year 1 Monthly Rate ($) | C25: 625 | E25: Total Savings From Base | F25: - | G25: =SUM(G22:G24) -> 109033.79 | H25: =SUM(H22:H24) -> 218067.58 | I25: =SUM(I22:I24) -> 327101.36
B26: Other Items Year 1 Monthly Rate ($) | C26: 312.5 | E26: NPV | F26: {=SUMPRODUCT(($C$75:$C$198>=IF($C$13=0,1,$C$13))*N$75:N$198/(1+$F$12/12)^($C$75:$C$198-IF($C$13=0,0,$C$13)+1))} -> 1638686.8 | G26: {=SUMPRODUCT(($C$75:$C$198>=IF($C$13=0,1,$C$13))*T$75:T$198/(1+$F$12/12)^($C$75:$C$198-IF($C$13=0,0,$C$13)+1))} -> 1555861 | H26: {=SUMPRODUCT(($C$75:$C$198>=IF($C$13=0,1,$C$13))*U$75:U$198/(1+$F$12/12)^($C$75:$C$198-IF($C$13=0,0,$C$13)+1))} -> 1473035.3 | I26: {=SUMPRODUCT(($C$75:$C$198>=IF($C$13=0,1,$C$13))*V$75:V$198/(1+$F$12/12)^($C$75:$C$198-IF($C$13=0,0,$C$13)+1))} -> 1390209.5
E27: NPV Savings vs Base | F27: - | G27: =F26-G26 -> 82825.762 | H27: =F26-H26 -> 165651.52 | I27: =F26-I26 -> 248477.29
B28: Escalations: | E28: % Savings vs Base | F28: - | G28: =IFERROR((F26-G26)/F26,0) -> 0.050543986 | H28: =IFERROR((F26-H26)/F26,0) -> 0.10108797 | I28: =IFERROR((F26-I26)/F26,0) -> 0.15163196
B29: Annual Base Rent Escalation Rate (%) | C29: 0.03 | E29: Full-Lease FV (all months, no date filter) | F29: =SUM(N75:N198) -> 2691076.8 | G29: =SUM(T75:T198) -> 2555948.5 | H29: =SUM(U75:U198) -> 2420820.2 | I29: =SUM(V75:V198) -> 2285691.9
B30: CAMS Annual Escalation Rate (%) | C30: 0.03 | E30: Cross-check: NNN after discount (orphan) | F30: =F18*(1-F15) -> 10258.25 | G30: =F18*(1-G15) -> 9232.425 | H30: =F18*(1-H15) -> 8206.6 | I30: =F18*(1-I15) -> 7180.775
B31: Insurance Annual Escalation Rate (%) | C31: 0.03
B32: Taxes Annual Escalation Rate (%) | C32: 0.03 | E32: SCENARIO COMPARISON - exit | F32: Effective Date of Analysis: | G32: =C12 -> 44205
B33: Security Annual Escalation Rate (%) | C33: 0.02 | F33: Full Obligation | G33: Mild Discount | H33: Moderate Discount | I33: Material Discount | J33: Significant Discount
B34: Other Items Annual Escalation Rate (%) | C34: 0.02 | E34: % Buyout | F34: 0 | G34: 0.2 | H34: 0.3 | I34: 0.4 | J34: 0.5
E35: Monthly Base Rent | F35: =F16 -> 10609 | G35: =F35 -> 10609 | H35: =F35 -> 10609 | I35: =F35 -> 10609 | J35: =F35 -> 10609
B36: Abatement: | E36: Base/$PSF | F36: =IF($C$7=0,0,F35/$C$7) -> 0.70726667 | G36: =IF($C$7=0,0,G35/$C$7) -> 0.70726667 | H36: =IF($C$7=0,0,H35/$C$7) -> 0.70726667 | I36: =IF($C$7=0,0,I35/$C$7) -> 0.70726667 | J36: =IF($C$7=0,0,J35/$C$7) -> 0.70726667
B37: Abatement duration (months) | C37: 1 | E37: Additional Rent (NNN) | F37: =F18 -> 10258.25 | G37: =F37 -> 10258.25 | H37: =F37 -> 10258.25 | I37: =F37 -> 10258.25
B38: Abatement start | C38: 43956 | E38: Total Occupancy Cost | F38: =F35+F37 -> 20867.25 | G38: =G35+G37 -> 20867.25 | H38: =H35+H37 -> 20867.25 | I38: =I35+I37 -> 20867.25
B39: Abatement end | C39: 44321 | E39: Effective $/PSF | F39: =IF($C$7=0,0,F38/$C$7) -> 1.39115 | G39: =IF($C$7=0,0,G38/$C$7) -> 1.39115 | H39: =IF($C$7=0,0,H38/$C$7) -> 1.39115 | I39: =IF($C$7=0,0,I38/$C$7) -> 1.39115
B40: Abatement % of full rent (dependent, don't change) | C40: =IF(C21=0,0,C41/C21) -> 0.3 | E40: Remaining Obligation (FV) | F40: =F21 -> 2153223.6 | G40: =F40*(1-G34) -> 1722578.9 | H40: =F40*(1-H34) -> 1507256.6 | I40: =F40*(1-I34) -> 1291934.2 | J40: =F40*(1-J34) -> 1076611.8
A41: 13 | B41: Abatement amt (dollars) | C41: 3000 | E41: Gross Savings vs Base ($) | F41: =0 -> 0 | G41: =F40-G40 -> 430644.73 | H41: =F40-H40 -> 645967.09 | I41: =F40-I40 -> 861289.46 | J41: =F40-J40 -> 1076611.8
A42: 14 | B42: *Additional abatement later in lease? (If yes, view the lease schedule abatement column and hardcode your values) | C42: yes | E42: (+)Free Rent | G42: =F35*$F$42 -> 0 | H42: =F35*$F$42 -> 0 | I42: =F35*$F$42 -> 0
...

Sheet Annual Summary
A1: Period Start | B1: Period End | C1: Lease Year | D1: Months | E1: Base Rent Applied | F1: Total NNN | G1: Total Monthly Obligation | H1: % of Grand Total
A2: 43160 | B2: 43524 | C2: 1 | D2: =COUNTIF('Lease Schedule (populated)'!$D$75:$D$198,1) -> 12 | E2: =SUMIF('Lease Schedule (populated)'!$D$75:$D$198,1,'Lease Schedule (populated)'!$F$75:$F$198) -> 120000 | F2: =SUMIF('Lease Schedule (populated)'!$D$75:$D$198,1,'Lease Schedule (populated)'!$M$75:$M$198) -> 116250 | G2: =SUMIF('Lease Schedule (populated)'!$D$75:$D$198,1,'Lease Schedule (populated)'!$N$75:$N$198) -> 236250 | H2: =IF(G13=0,0,G2/G13) -> 0.087790135
A3: 43525 | B3: 43890 | C3: 2 | D3: =COUNTIF('Lease Schedule (populated)'!$D$75:$D$198,2) -> 12 | E3: =SUMIF('Lease Schedule (populated)'!$D$75:$D$198,2,'Lease Schedule (populated)'!$F$75:$F$198) -> 111240 | F3: =SUMIF('Lease Schedule (populated)'!$D$75:$D$198,2,'Lease Schedule (populated)'!$M$75:$M$198) -> 119625 | G3: =SUMIF('Lease Schedule (populated)'!$D$75:$D$198,2,'Lease Schedule (populated)'!$N$75:$N$198) -> 230865 | H3: =IF(G13=0,0,G3/G13) -> 0.085789077
A4: 43891 | B4: 44255 | C4: 3 | D4: =COUNTIF('Lease Schedule (populated)'!$D$75:$D$198,3) -> 12 | E4: =SUMIF('Lease Schedule (populated)'!$D$75:$D$198,3,'Lease Schedule (populated)'!$F$75:$F$198) -> 101846.4 | F4: =SUMIF('Lease Schedule (populated)'!$D$75:$D$198,3,'Lease Schedule (populated)'!$M$75:$M$198) -> 123099 | G4: =SUMIF('Lease Schedule (populated)'!$D$75:$D$198,3,'Lease Schedule (populated)'!$N$75:$N$198) -> 224945.4 | H4: =IF(G13=0,0,G4/G13) -> 0.083589363
A5: 44256 | B5: 44620 | C5: 4 | D5: =COUNTIF('Lease Schedule (populated)'!$D$75:$D$198,4) -> 12 | E5: =SUMIF('Lease Schedule (populated)'!$D$75:$D$198,4,'Lease Schedule (populated)'!$F$75:$F$198) -> 131127.24 | F5: =SUMIF('Lease Schedule (populated)'!$D$75:$D$198,4,'Lease Schedule (populated)'!$M$75:$M$198) -> 126674.92 | G5: =SUMIF('Lease Schedule (populated)'!$D$75:$D$198,4,'Lease Schedule (populated)'!$N$75:$N$198) -> 257802.16 | H5: =IF(G13=0,0,G5/G13) -> 0.095798886
A6: 44621 | B6: 44985 | C6: 5 | D6: =COUNTIF('Lease Schedule (populated)'!$D$75:$D$198,5) -> 12 | E6: =SUMIF('Lease Schedule (populated)'!$D$75:$D$198,5,'Lease Schedule (populated)'!$F$75:$F$198) -> 135061.06 | F6: =SUMIF('Lease Schedule (populated)'!$D$75:$D$198,5,'Lease Schedule (populated)'!$M$75:$M$198) -> 130355.79 | G6: =SUMIF('Lease Schedule (populated)'!$D$75:$D$198,5,'Lease Schedule (populated)'!$N$75:$N$198) -> 265416.84 | H6: =IF(G13=0,0,G6/G13) -> 0.098628489
A7: 44986 | B7: 45351 | C7: 6 | D7: =COUNTIF('Lease Schedule (populated)'!$D$75:$D$198,6) -> 12 | E7: =SUMIF('Lease Schedule (populated)'!$D$75:$D$198,6,'Lease Schedule (populated)'!$F$75:$F$198) -> 139112.89 | F7: =SUMIF('Lease Schedule (populated)'!$D$75:$D$198,6,'Lease Schedule (populated)'!$M$75:$M$198) -> 134144.69 | G7: =SUMIF('Lease Schedule (populated)'!$D$75:$D$198,6,'Lease Schedule (populated)'!$N$75:$N$198) -> 273257.58 | H7: =IF(G13=0,0,G7/G13) -> 0.10154209
A8: 45352 | B8: 45716 | C8: 7 | D8: =COUNTIF('Lease Schedule (populated)'!$D$75:$D$198,7) -> 12 | E8: =SUMIF('Lease Schedule (populated)'!$D$75:$D$198,7,'Lease Schedule (populated)'!$F$75:$F$198) -> 143286.28 | F8: =SUMIF('Lease Schedule (populated)'!$D$75:$D$198,7,'Lease Schedule (populated)'!$M$75:$M$198) -> 138044.82 | G8: =SUMIF('Lease Schedule (populated)'!$D$75:$D$198,7,'Lease Schedule (populated)'!$N$75:$N$198) -> 281331.09 | H8: =IF(G13=0,0,G8/G13) -> 0.1045422
A9: 45717 | B9: 46081 | C9: 8 | D9: =COUNTIF('Lease Schedule (populated)'!$D$75:$D$198,8) -> 12 | E9: =SUMIF('Lease Schedule (populated)'!$D$75:$D$198,8,'Lease Schedule (populated)'!$F$75:$F$198) -> 147584.86 | F9: =SUMIF('Lease Schedule (populated)'!$D$75:$D$198,8,'Lease Schedule (populated)'!$M$75:$M$198) -> 142059.47 | G9: =SUMIF('Lease Schedule (populated)'!$D$75:$D$198,8,'Lease Schedule (populated)'!$N$75:$N$198) -> 289644.33 | H9: =IF(G13=0,0,G9/G13) -> 0.10763139
A10: 46082 | B10: 46446 | C10: 9 | D10: =COUNTIF('Lease Schedule (populated)'!$D$75:$D$198,9) -> 12 | E10: =SUMIF('Lease Schedule (populated)'!$D$75:$D$198,9,'Lease Schedule (populated)'!$F$75:$F$198) -> 152012.41 | F10: =SUMIF('Lease Schedule (populated)'!$D$75:$D$198,9,'Lease Schedule (populated)'!$M$75:$M$198) -> 146192.03 | G10: =SUMIF('Lease Schedule (populated)'!$D$75:$D$198,9,'Lease Schedule (populated)'!$N$75:$N$198) -> 298204.44 | H10: =IF(G13=0,0,G10/G13) -> 0.11081231
A11: 46447 | B11: 46812 | C11: 10 | D11: =COUNTIF('Lease Schedule (populated)'!$D$75:$D$198,10) -> 12 | E11: =SUMIF('Lease Schedule (populated)'!$D$75:$D$198,10,'Lease Schedule (populated)'!$F$75:$F$198) -> 156572.78 | F11: =SUMIF('Lease Schedule (populated)'!$D$75:$D$198,10,'Lease Schedule (populated)'!$M$75:$M$198) -> 150445.98 | G11: =SUMIF('Lease Schedule (populated)'!$D$75:$D$198,10,'Lease Schedule (populated)'!$N$75:$N$198) -> 307018.76 | H11: =IF(G13=0,0,G11/G13) -> 0.1140877
A12: 46813 | B12: 46934 | C12: 11 (Stub) | D12: =COUNTIF('Lease Schedule (populated)'!$D$75:$D$198,11) -> 4 | E12: =SUMIF('Lease Schedule (populated)'!$D$75:$D$198,11,'Lease Schedule (populated)'!$F$75:$F$198) -> 13439.164 | F12: =SUMIF('Lease Schedule (populated)'!$D$75:$D$198,11,'Lease Schedule (populated)'!$M$75:$M$198) -> 12902.076 | G12: =SUMIF('Lease Schedule (populated)'!$D$75:$D$198,11,'Lease Schedule (populated)'!$N$75:$N$198) -> 26341.239 | H12: =IF(G13=0,0,G12/G13) -> 0.0097883639
A13: GRAND TOTAL | D13: =SUM(D2:D12) -> 124 | E13: =SUM(E2:E12) -> 1351283.1 | F13: =SUM(F2:F12) -> 1339793.8 | G13: =SUM(G2:G12) -> 2691076.8 | H13: =SUM(H2:H12) -> 1

Sheet Audit Trail
A1: Period Start | B1: Month # | C1: Period Factor | D1: Proration Factor | E1: Proration Basis | F1: CAMS Esc Year | G1: CAMS Active | H1: Ins Esc Year | I1: Ins Active | J1: Tax Esc Year | K1: Tax Active | L1: Sec Esc Year | M1: Sec Active | N1: Other Esc Year | O1: Other Active
A2: 43160 | B2: 1 | C2: 1 | D2: 0 | E2: full | F2: 0 | G2: true | H2: 0 | I2: true | J2: 0 | K2: true | L2: 0 | M2: true | N2: 0 | O2: true
A3: 43191 | B3: 2 | C3: 1 | D3: 0 | E3: full | F3: 0 | G3: true | H3: 0 | I3: true | J3: 0 | K3: true | L3: 0 | M3: true | N3: 0 | O3: true
A4: 43221 | B4: 3 | C4: 1 | D4: 0 | E4: full | F4: 0 | G4: true | H4: 0 | I4: true | J4: 0 | K4: true | L4: 0 | M4: true | N4: 0 | O4: true
A5: 43252 | B5: 4 | C5: 1 | D5: 0 | E5: full | F5: 0 | G5: true | H5: 0 | I5: true | J5: 0 | K5: true | L5: 0 | M5: true | N5: 0 | O5: true
A6: 43282 | B6: 5 | C6: 1 | D6: 1 | E6: full | F6: 0 | G6: true | H6: 0 | I6: true | J6: 0 | K6: true | L6: 0 | M6: true | N6: 0 | O6: true
A7: 43313 | B7: 6 | C7: 1 | D7: 1 | E7: full | F7: 0 | G7: true | H7: 0 | I7: true | J7: 0 | K7: true | L7: 0 | M7: true | N7: 0 | O7: true
A8: 43344 | B8: 7 | C8: 1 | D8: 1 | E8: full | F8: 0 | G8: true | H8: 0 | I8: true | J8: 0 | K8: true | L8: 0 | M8: true | N8: 0 | O8: true
A9: 43374 | B9: 8 | C9: 1 | D9: 1 | E9: full | F9: 0 | G9: true | H9: 0 | I9: true | J9: 0 | K9: true | L9: 0 | M9: true | N9: 0 | O9: true
A10: 43405 | B10: 9 | C10: 1 | D10: 1 | E10: full | F10: 0 | G10: true | H10: 0 | I10: true | J10: 0 | K10: true | L10: 0 | M10: true | N10: 0 | O10: true
A11: 43435 | B11: 10 | C11: 1 | D11: 1 | E11: full | F11: 0 | G11: true | H11: 0 | I11: true | J11: 0 | K11: true | L11: 0 | M11: true | N11: 0 | O11: true
A12: 43466 | B12: 11 | C12: 1 | D12: 1 | E12: full | F12: 0 | G12: true | H12: 0 | I12: true | J12: 0 | K12: true | L12: 0 | M12: true | N12: 0 | O12: true
A13: 43497 | B13: 12 | C13: 1 | D13: 1 | E13: full | F13: 0 | G13: true | H13: 0 | I13: true | J13: 0 | K13: true | L13: 0 | M13: true | N13: 0 | O13: true
... A125: 46905 | B125: 124 | C125: 1 | D125: 1 | E125: full | F125: 8 | G125: true | H125: 8 | I125: true | J125: 9 | K125: true | L125: 0 | M125: true | N125: 0 | O125: true
